<?xml version='1.0' encoding='UTF-8'?>
<mujoco>
    <option timestep="1e-5"/>
    <option gravity="0 0 0"/>
    <option integrator="implicitfast"/>
    <!--Euler, RK4, implicit, implicitfast-->
   
    <asset>
        <texture type="skybox" builtin="gradient" rgb1="1 1 1" rgb2="1 1 1" width="265" height="256"/>
        <texture name="grid" type="2d" builtin="checker" rgb1="0.1 0.2 0.3" rgb2="0.2 0.3 0.4" width="300" height="300"/>
        <material name="grid" texture="grid" texrepeat="10 10" reflectance="0.2"/>
    </asset>

    <default class="main"> 
        <geom condim="1" contype="1" conaffinity="0" solref="0.0001 12"/>
        <equality solref="0.0001 12"/>
    </default>

    <worldbody>

    <light pos="0 0 100"/>
    <camera name="side view" pos="0 -0.3 0.025" euler="90 0 0" orthographic="true" fovy="0.1"/>





    <body name="IDF_b_0" pos="0 0 0" euler="0 0 0">
<site name="IDF_b_0_sroot" size="0.0001" pos="0 0 0"/>
<geom name="IDF_b_0_g" type="box" size="0.001 0.0175 0.0008750000000000001" pos="0 0 0.0008750000000000001" rgba="0.1 0.1 0.1 0.5"/>
<site name="IDF_b_0_s" size="0.0001" pos="0 0 0.0008750000000000001"/>
<body name="IDF_b_1" pos="0 0 0.0017500000000000003" euler="0 0 0">
<joint name="IDF_b_1_j" type="hinge" axis="0 1 0" pos="0 0 0" stiffness="0.12333333333333335" damping="0.0006166666666666667"/>
<geom name="IDF_b_1_g" type="box" size="0.001 0.0175 0.0017500000000000003" pos="0 0 0.0017500000000000003" rgba="0.1 0.1 0.1 0.5"/>
<site name="IDF_b_1_s" size="0.0001" pos="0 0 0.0017500000000000003"/>
<body name="IDF_b_2" pos="0 0 0.0035000000000000005" euler="0 0 0">
<joint name="IDF_b_2_j" type="hinge" axis="0 1 0" pos="0 0 0" stiffness="0.12333333333333335" damping="0.0006166666666666667"/>
<geom name="IDF_b_2_g" type="box" size="0.001 0.0175 0.0017500000000000003" pos="0 0 0.0017500000000000003" rgba="0.1 0.1 0.1 0.5"/>
<site name="IDF_b_2_s" size="0.0001" pos="0 0 0.0017500000000000003"/>
<body name="IDF_b_3" pos="0 0 0.0035000000000000005" euler="0 0 0">
<joint name="IDF_b_3_j" type="hinge" axis="0 1 0" pos="0 0 0" stiffness="0.12333333333333335" damping="0.0006166666666666667"/>
<geom name="IDF_b_3_g" type="box" size="0.001 0.0175 0.0017500000000000003" pos="0 0 0.0017500000000000003" rgba="0.1 0.1 0.1 0.5"/>
<site name="IDF_b_3_s" size="0.0001" pos="0 0 0.0017500000000000003"/>
<body name="IDF_b_4" pos="0 0 0.0035000000000000005" euler="0 0 0">
<joint name="IDF_b_4_j" type="hinge" axis="0 1 0" pos="0 0 0" stiffness="0.12333333333333335" damping="0.0006166666666666667"/>
<geom name="IDF_b_4_g" type="box" size="0.001 0.0175 0.0017500000000000003" pos="0 0 0.0017500000000000003" rgba="0.1 0.1 0.1 0.5"/>
<site name="IDF_b_4_s" size="0.0001" pos="0 0 0.0017500000000000003"/>
<body name="IDF_b_5" pos="0 0 0.0035000000000000005" euler="0 0 0">
<joint name="IDF_b_5_j" type="hinge" axis="0 1 0" pos="0 0 0" stiffness="0.12333333333333335" damping="0.0006166666666666667"/>
<geom name="IDF_b_5_g" type="box" size="0.001 0.0175 0.0017500000000000003" pos="0 0 0.0017500000000000003" rgba="0.1 0.1 0.1 0.5"/>
<site name="IDF_b_5_s" size="0.0001" pos="0 0 0.0017500000000000003"/>
<body name="IDF_b_6" pos="0 0 0.0035000000000000005" euler="0 0 0">
<joint name="IDF_b_6_j" type="hinge" axis="0 1 0" pos="0 0 0" stiffness="0.12333333333333335" damping="0.0006166666666666667"/>
<geom name="IDF_b_6_g" type="box" size="0.001 0.0175 0.0017500000000000003" pos="0 0 0.0017500000000000003" rgba="0.1 0.1 0.1 0.5"/>
<site name="IDF_b_6_s" size="0.0001" pos="0 0 0.0017500000000000003"/>
<body name="IDF_b_7" pos="0 0 0.0035000000000000005" euler="0 0 0">
<joint name="IDF_b_7_j" type="hinge" axis="0 1 0" pos="0 0 0" stiffness="0.12333333333333335" damping="0.0006166666666666667"/>
<geom name="IDF_b_7_g" type="box" size="0.001 0.0175 0.0017500000000000003" pos="0 0 0.0017500000000000003" rgba="0.1 0.1 0.1 0.5"/>
<site name="IDF_b_7_s" size="0.0001" pos="0 0 0.0017500000000000003"/>
<body name="IDF_b_8" pos="0 0 0.0035000000000000005" euler="0 0 0">
<joint name="IDF_b_8_j" type="hinge" axis="0 1 0" pos="0 0 0" stiffness="0.12333333333333335" damping="0.0006166666666666667"/>
<geom name="IDF_b_8_g" type="box" size="0.001 0.0175 0.0017500000000000003" pos="0 0 0.0017500000000000003" rgba="0.1 0.1 0.1 0.5"/>
<site name="IDF_b_8_s" size="0.0001" pos="0 0 0.0017500000000000003"/>
<body name="IDF_b_9" pos="0 0 0.0035000000000000005" euler="0 0 0">
<joint name="IDF_b_9_j" type="hinge" axis="0 1 0" pos="0 0 0" stiffness="0.12333333333333335" damping="0.0006166666666666667"/>
<geom name="IDF_b_9_g" type="box" size="0.001 0.0175 0.0017500000000000003" pos="0 0 0.0017500000000000003" rgba="0.1 0.1 0.1 0.5"/>
<site name="IDF_b_9_s" size="0.0001" pos="0 0 0.0017500000000000003"/>
<body name="IDF_b_10" pos="0 0 0.0035000000000000005" euler="0 0 0">
<joint name="IDF_b_10_j" type="hinge" axis="0 1 0" pos="0 0 0" stiffness="0.12333333333333335" damping="0.0006166666666666667"/>
<geom name="IDF_b_10_g" type="box" size="0.001 0.0175 0.0017500000000000003" pos="0 0 0.0017500000000000003" rgba="0.1 0.1 0.1 0.5"/>
<site name="IDF_b_10_s" size="0.0001" pos="0 0 0.0017500000000000003"/>
<body name="IDF_b_11" pos="0 0 0.0035000000000000005" euler="0 0 0">
<joint name="IDF_b_11_j" type="hinge" axis="0 1 0" pos="0 0 0" stiffness="0.12333333333333335" damping="0.0006166666666666667"/>
<geom name="IDF_b_11_g" type="box" size="0.001 0.0175 0.0017500000000000003" pos="0 0 0.0017500000000000003" rgba="0.1 0.1 0.1 0.5"/>
<site name="IDF_b_11_s" size="0.0001" pos="0 0 0.0017500000000000003"/>
<body name="IDF_b_12" pos="0 0 0.0035000000000000005" euler="0 0 0">
<joint name="IDF_b_12_j" type="hinge" axis="0 1 0" pos="0 0 0" stiffness="0.12333333333333335" damping="0.0006166666666666667"/>
<geom name="IDF_b_12_g" type="box" size="0.001 0.0175 0.0017500000000000003" pos="0 0 0.0017500000000000003" rgba="0.1 0.1 0.1 0.5"/>
<site name="IDF_b_12_s" size="0.0001" pos="0 0 0.0017500000000000003"/>
<body name="IDF_b_13" pos="0 0 0.0035000000000000005" euler="0 0 0">
<joint name="IDF_b_13_j" type="hinge" axis="0 1 0" pos="0 0 0" stiffness="0.12333333333333335" damping="0.0006166666666666667"/>
<geom name="IDF_b_13_g" type="box" size="0.001 0.0175 0.0017500000000000003" pos="0 0 0.0017500000000000003" rgba="0.1 0.1 0.1 0.5"/>
<site name="IDF_b_13_s" size="0.0001" pos="0 0 0.0017500000000000003"/>
<body name="IDF_b_14" pos="0 0 0.0035000000000000005" euler="0 0 0">
<joint name="IDF_b_14_j" type="hinge" axis="0 1 0" pos="0 0 0" stiffness="0.12333333333333335" damping="0.0006166666666666667"/>
<geom name="IDF_b_14_g" type="box" size="0.001 0.0175 0.0017500000000000003" pos="0 0 0.0017500000000000003" rgba="0.1 0.1 0.1 0.5"/>
<site name="IDF_b_14_s" size="0.0001" pos="0 0 0.0017500000000000003"/>
<body name="IDF_b_15" pos="0 0 0.0035000000000000005" euler="0 0 0">
<joint name="IDF_b_15_j" type="hinge" axis="0 1 0" pos="0 0 0" stiffness="0.12333333333333335" damping="0.0006166666666666667"/>
<geom name="IDF_b_15_g" type="box" size="0.001 0.0175 0.0017500000000000003" pos="0 0 0.0017500000000000003" rgba="0.1 0.1 0.1 0.5"/>
<site name="IDF_b_15_s" size="0.0001" pos="0 0 0.0017500000000000003"/>
<body name="IDF_b_16" pos="0 0 0.0035000000000000005" euler="0 0 0">
<joint name="IDF_b_16_j" type="hinge" axis="0 1 0" pos="0 0 0" stiffness="0.12333333333333335" damping="0.0006166666666666667"/>
<geom name="IDF_b_16_g" type="box" size="0.001 0.0175 0.0017500000000000003" pos="0 0 0.0017500000000000003" rgba="0.1 0.1 0.1 0.5"/>
<site name="IDF_b_16_s" size="0.0001" pos="0 0 0.0017500000000000003"/>
<body name="IDF_b_17" pos="0 0 0.0035000000000000005" euler="0 0 0">
<joint name="IDF_b_17_j" type="hinge" axis="0 1 0" pos="0 0 0" stiffness="0.12333333333333335" damping="0.0006166666666666667"/>
<geom name="IDF_b_17_g" type="box" size="0.001 0.0175 0.0017500000000000003" pos="0 0 0.0017500000000000003" rgba="0.1 0.1 0.1 0.5"/>
<site name="IDF_b_17_s" size="0.0001" pos="0 0 0.0017500000000000003"/>
<body name="IDF_b_18" pos="0 0 0.0035000000000000005" euler="0 0 0">
<joint name="IDF_b_18_j" type="hinge" axis="0 1 0" pos="0 0 0" stiffness="0.12333333333333335" damping="0.0006166666666666667"/>
<geom name="IDF_b_18_g" type="box" size="0.001 0.0175 0.0017500000000000003" pos="0 0 0.0017500000000000003" rgba="0.1 0.1 0.1 0.5"/>
<site name="IDF_b_18_s" size="0.0001" pos="0 0 0.0017500000000000003"/>
<body name="IDF_b_19" pos="0 0 0.0035000000000000005" euler="0 0 0">
<joint name="IDF_b_19_j" type="hinge" axis="0 1 0" pos="0 0 0" stiffness="0.12333333333333335" damping="0.0006166666666666667"/>
<geom name="IDF_b_19_g" type="box" size="0.001 0.0175 0.0017500000000000003" pos="0 0 0.0017500000000000003" rgba="0.1 0.1 0.1 0.5"/>
<site name="IDF_b_19_s" size="0.0001" pos="0 0 0.0017500000000000003"/>
<body name="IDF_b_20" pos="0 0 0.0035000000000000005" euler="0 0 0">
<joint name="IDF_b_20_j" type="hinge" axis="0 1 0" pos="0 0 0" stiffness="0.12333333333333335" damping="0.0006166666666666667"/>
<geom name="IDF_b_20_g" type="box" size="0.001 0.0175 0.0008750000000000001" pos="0 0 0.0008750000000000001" rgba="0.1 0.1 0.1 0.5"/>
<site name="IDF_b_20_s" size="0.0001" pos="0 0 0.0008750000000000001"/>
<site name="IDF_b_21_s" size="0.0001" pos="0 0 0.0017500000000000003"/>
</body>
</body>
</body>
</body>
</body>
</body>
</body>
</body>
</body>
</body>
</body>
</body>
</body>
</body>
<site name="IDF_b_6_conn_0" size="0.0001" pos="0 0 0.0007500000000000007" rgba="1 0 0 1"/><site name="IDF_b_6_conn_1" size="0.0001" pos="0 0 0.002513269807084651" rgba="1 0 0 1"/></body>
<site name="IDF_b_5_conn_2" size="0.0001" pos="0 0 0.00248673019291535" rgba="1 0 0 1"/></body>
</body>
</body>
</body>
</body>
</body><body name="IDB_b_0" pos="0.035 0 0" euler="0 -26.565051177077994 0">
<site name="IDB_b_0_sroot" size="0.0001" pos="0 0 0"/>
<geom name="IDB_b_0_g" type="box" size="0.001 0.0175 0.000978279740156158" pos="0 0 0.000978279740156158" rgba="0.1 0.1 0.1 0.5"/>
<site name="IDB_b_0_s" size="0.0001" pos="0 0 0.000978279740156158"/>
<body name="IDB_b_1" pos="0 0 0.001956559480312316" euler="0 0 0">
<joint name="IDB_b_1_j" type="hinge" axis="0 1 0" pos="0 0 0" stiffness="0.11031268688998966" damping="0.0005515634344499483"/>
<geom name="IDB_b_1_g" type="box" size="0.001 0.0175 0.001956559480312316" pos="0 0 0.001956559480312316" rgba="0.1 0.1 0.1 0.5"/>
<site name="IDB_b_1_s" size="0.0001" pos="0 0 0.001956559480312316"/>
<body name="IDB_b_2" pos="0 0 0.003913118960624632" euler="0 0 0">
<joint name="IDB_b_2_j" type="hinge" axis="0 1 0" pos="0 0 0" stiffness="0.11031268688998966" damping="0.0005515634344499483"/>
<geom name="IDB_b_2_g" type="box" size="0.001 0.0175 0.001956559480312316" pos="0 0 0.001956559480312316" rgba="0.1 0.1 0.1 0.5"/>
<site name="IDB_b_2_s" size="0.0001" pos="0 0 0.001956559480312316"/>
<body name="IDB_b_3" pos="0 0 0.003913118960624632" euler="0 0 0">
<joint name="IDB_b_3_j" type="hinge" axis="0 1 0" pos="0 0 0" stiffness="0.11031268688998966" damping="0.0005515634344499483"/>
<geom name="IDB_b_3_g" type="box" size="0.001 0.0175 0.001956559480312316" pos="0 0 0.001956559480312316" rgba="0.1 0.1 0.1 0.5"/>
<site name="IDB_b_3_s" size="0.0001" pos="0 0 0.001956559480312316"/>
<body name="IDB_b_4" pos="0 0 0.003913118960624632" euler="0 0 0">
<joint name="IDB_b_4_j" type="hinge" axis="0 1 0" pos="0 0 0" stiffness="0.11031268688998966" damping="0.0005515634344499483"/>
<geom name="IDB_b_4_g" type="box" size="0.001 0.0175 0.001956559480312316" pos="0 0 0.001956559480312316" rgba="0.1 0.1 0.1 0.5"/>
<site name="IDB_b_4_s" size="0.0001" pos="0 0 0.001956559480312316"/>
<body name="IDB_b_5" pos="0 0 0.003913118960624632" euler="0 0 0">
<joint name="IDB_b_5_j" type="hinge" axis="0 1 0" pos="0 0 0" stiffness="0.11031268688998966" damping="0.0005515634344499483"/>
<geom name="IDB_b_5_g" type="box" size="0.001 0.0175 0.001956559480312316" pos="0 0 0.001956559480312316" rgba="0.1 0.1 0.1 0.5"/>
<site name="IDB_b_5_s" size="0.0001" pos="0 0 0.001956559480312316"/>
<body name="IDB_b_6" pos="0 0 0.003913118960624632" euler="0 0 0">
<joint name="IDB_b_6_j" type="hinge" axis="0 1 0" pos="0 0 0" stiffness="0.11031268688998966" damping="0.0005515634344499483"/>
<geom name="IDB_b_6_g" type="box" size="0.001 0.0175 0.001956559480312316" pos="0 0 0.001956559480312316" rgba="0.1 0.1 0.1 0.5"/>
<site name="IDB_b_6_s" size="0.0001" pos="0 0 0.001956559480312316"/>
<body name="IDB_b_7" pos="0 0 0.003913118960624632" euler="0 0 0">
<joint name="IDB_b_7_j" type="hinge" axis="0 1 0" pos="0 0 0" stiffness="0.11031268688998966" damping="0.0005515634344499483"/>
<geom name="IDB_b_7_g" type="box" size="0.001 0.0175 0.001956559480312316" pos="0 0 0.001956559480312316" rgba="0.1 0.1 0.1 0.5"/>
<site name="IDB_b_7_s" size="0.0001" pos="0 0 0.001956559480312316"/>
<body name="IDB_b_8" pos="0 0 0.003913118960624632" euler="0 0 0">
<joint name="IDB_b_8_j" type="hinge" axis="0 1 0" pos="0 0 0" stiffness="0.11031268688998966" damping="0.0005515634344499483"/>
<geom name="IDB_b_8_g" type="box" size="0.001 0.0175 0.001956559480312316" pos="0 0 0.001956559480312316" rgba="0.1 0.1 0.1 0.5"/>
<site name="IDB_b_8_s" size="0.0001" pos="0 0 0.001956559480312316"/>
<body name="IDB_b_9" pos="0 0 0.003913118960624632" euler="0 0 0">
<joint name="IDB_b_9_j" type="hinge" axis="0 1 0" pos="0 0 0" stiffness="0.11031268688998966" damping="0.0005515634344499483"/>
<geom name="IDB_b_9_g" type="box" size="0.001 0.0175 0.001956559480312316" pos="0 0 0.001956559480312316" rgba="0.1 0.1 0.1 0.5"/>
<site name="IDB_b_9_s" size="0.0001" pos="0 0 0.001956559480312316"/>
<body name="IDB_b_10" pos="0 0 0.003913118960624632" euler="0 0 0">
<joint name="IDB_b_10_j" type="hinge" axis="0 1 0" pos="0 0 0" stiffness="0.11031268688998966" damping="0.0005515634344499483"/>
<geom name="IDB_b_10_g" type="box" size="0.001 0.0175 0.001956559480312316" pos="0 0 0.001956559480312316" rgba="0.1 0.1 0.1 0.5"/>
<site name="IDB_b_10_s" size="0.0001" pos="0 0 0.001956559480312316"/>
<body name="IDB_b_11" pos="0 0 0.003913118960624632" euler="0 0 0">
<joint name="IDB_b_11_j" type="hinge" axis="0 1 0" pos="0 0 0" stiffness="0.11031268688998966" damping="0.0005515634344499483"/>
<geom name="IDB_b_11_g" type="box" size="0.001 0.0175 0.001956559480312316" pos="0 0 0.001956559480312316" rgba="0.1 0.1 0.1 0.5"/>
<site name="IDB_b_11_s" size="0.0001" pos="0 0 0.001956559480312316"/>
<body name="IDB_b_12" pos="0 0 0.003913118960624632" euler="0 0 0">
<joint name="IDB_b_12_j" type="hinge" axis="0 1 0" pos="0 0 0" stiffness="0.11031268688998966" damping="0.0005515634344499483"/>
<geom name="IDB_b_12_g" type="box" size="0.001 0.0175 0.001956559480312316" pos="0 0 0.001956559480312316" rgba="0.1 0.1 0.1 0.5"/>
<site name="IDB_b_12_s" size="0.0001" pos="0 0 0.001956559480312316"/>
<body name="IDB_b_13" pos="0 0 0.003913118960624632" euler="0 0 0">
<joint name="IDB_b_13_j" type="hinge" axis="0 1 0" pos="0 0 0" stiffness="0.11031268688998966" damping="0.0005515634344499483"/>
<geom name="IDB_b_13_g" type="box" size="0.001 0.0175 0.001956559480312316" pos="0 0 0.001956559480312316" rgba="0.1 0.1 0.1 0.5"/>
<site name="IDB_b_13_s" size="0.0001" pos="0 0 0.001956559480312316"/>
<body name="IDB_b_14" pos="0 0 0.003913118960624632" euler="0 0 0">
<joint name="IDB_b_14_j" type="hinge" axis="0 1 0" pos="0 0 0" stiffness="0.11031268688998966" damping="0.0005515634344499483"/>
<geom name="IDB_b_14_g" type="box" size="0.001 0.0175 0.001956559480312316" pos="0 0 0.001956559480312316" rgba="0.1 0.1 0.1 0.5"/>
<site name="IDB_b_14_s" size="0.0001" pos="0 0 0.001956559480312316"/>
<body name="IDB_b_15" pos="0 0 0.003913118960624632" euler="0 0 0">
<joint name="IDB_b_15_j" type="hinge" axis="0 1 0" pos="0 0 0" stiffness="0.11031268688998966" damping="0.0005515634344499483"/>
<geom name="IDB_b_15_g" type="box" size="0.001 0.0175 0.001956559480312316" pos="0 0 0.001956559480312316" rgba="0.1 0.1 0.1 0.5"/>
<site name="IDB_b_15_s" size="0.0001" pos="0 0 0.001956559480312316"/>
<body name="IDB_b_16" pos="0 0 0.003913118960624632" euler="0 0 0">
<joint name="IDB_b_16_j" type="hinge" axis="0 1 0" pos="0 0 0" stiffness="0.11031268688998966" damping="0.0005515634344499483"/>
<geom name="IDB_b_16_g" type="box" size="0.001 0.0175 0.001956559480312316" pos="0 0 0.001956559480312316" rgba="0.1 0.1 0.1 0.5"/>
<site name="IDB_b_16_s" size="0.0001" pos="0 0 0.001956559480312316"/>
<body name="IDB_b_17" pos="0 0 0.003913118960624632" euler="0 0 0">
<joint name="IDB_b_17_j" type="hinge" axis="0 1 0" pos="0 0 0" stiffness="0.11031268688998966" damping="0.0005515634344499483"/>
<geom name="IDB_b_17_g" type="box" size="0.001 0.0175 0.001956559480312316" pos="0 0 0.001956559480312316" rgba="0.1 0.1 0.1 0.5"/>
<site name="IDB_b_17_s" size="0.0001" pos="0 0 0.001956559480312316"/>
<body name="IDB_b_18" pos="0 0 0.003913118960624632" euler="0 0 0">
<joint name="IDB_b_18_j" type="hinge" axis="0 1 0" pos="0 0 0" stiffness="0.11031268688998966" damping="0.0005515634344499483"/>
<geom name="IDB_b_18_g" type="box" size="0.001 0.0175 0.001956559480312316" pos="0 0 0.001956559480312316" rgba="0.1 0.1 0.1 0.5"/>
<site name="IDB_b_18_s" size="0.0001" pos="0 0 0.001956559480312316"/>
<body name="IDB_b_19" pos="0 0 0.003913118960624632" euler="0 0 0">
<joint name="IDB_b_19_j" type="hinge" axis="0 1 0" pos="0 0 0" stiffness="0.11031268688998966" damping="0.0005515634344499483"/>
<geom name="IDB_b_19_g" type="box" size="0.001 0.0175 0.001956559480312316" pos="0 0 0.001956559480312316" rgba="0.1 0.1 0.1 0.5"/>
<site name="IDB_b_19_s" size="0.0001" pos="0 0 0.001956559480312316"/>
<body name="IDB_b_20" pos="0 0 0.003913118960624632" euler="0 0 0">
<joint name="IDB_b_20_j" type="hinge" axis="0 1 0" pos="0 0 0" stiffness="0.11031268688998966" damping="0.0005515634344499483"/>
<geom name="IDB_b_20_g" type="box" size="0.001 0.0175 0.000978279740156158" pos="0 0 0.000978279740156158" rgba="0.1 0.1 0.1 0.5"/>
<site name="IDB_b_20_s" size="0.0001" pos="0 0 0.000978279740156158"/>
<site name="IDB_b_21_s" size="0.0001" pos="0 0 0.001956559480312316"/>
</body>
</body>
</body>
</body>
</body>
</body>
</body>
</body>
</body>
</body>
</body>
</body>
</body>
<site name="IDB_b_7_conn_1" size="0.0001" pos="0 0 0.003266259331056773" rgba="1 0 0 1"/></body>
<site name="IDB_b_6_conn_0" size="0.0001" pos="0 0 0.0008385254915624224" rgba="1 0 0 1"/></body>
</body>
<site name="IDB_b_4_conn_2" size="0.0001" pos="0 0 0.0010977440603179307" rgba="1 0 0 1"/></body>
</body>
</body>
</body>
</body><body>
<joint type="free"/>
<body name="IDR0_b_0" pos="0 0 0.02" euler="0 90.0 0">
<site name="IDR0_b_0_sroot" size="0.0001" pos="0 0 0"/>
<geom name="IDR0_b_0_g" type="box" size="0.0005 0.0175 0.0005208333333333333" pos="0 0 0.0005208333333333333" rgba="0.1 0.1 0.1 0.5"/>
<site name="IDR0_b_0_s" size="0.0001" pos="0 0 0.0005208333333333333"/>
<body name="IDR0_b_1" pos="0 0 0.0010416666666666667" euler="0 0 0">
<joint name="IDR0_b_1_j" type="hinge" axis="0 1 0" pos="0 0 0" stiffness="0.025900000000000006" damping="0.00012950000000000003"/>
<geom name="IDR0_b_1_g" type="box" size="0.0005 0.0175 0.0010416666666666667" pos="0 0 0.0010416666666666667" rgba="0.1 0.1 0.1 0.5"/>
<site name="IDR0_b_1_s" size="0.0001" pos="0 0 0.0010416666666666667"/>
<body name="IDR0_b_2" pos="0 0 0.0020833333333333333" euler="0 0 0">
<joint name="IDR0_b_2_j" type="hinge" axis="0 1 0" pos="0 0 0" stiffness="0.025900000000000006" damping="0.00012950000000000003"/>
<geom name="IDR0_b_2_g" type="box" size="0.0005 0.0175 0.0010416666666666667" pos="0 0 0.0010416666666666667" rgba="0.1 0.1 0.1 0.5"/>
<site name="IDR0_b_2_s" size="0.0001" pos="0 0 0.0010416666666666667"/>
<body name="IDR0_b_3" pos="0 0 0.0020833333333333333" euler="0 0 0">
<joint name="IDR0_b_3_j" type="hinge" axis="0 1 0" pos="0 0 0" stiffness="0.025900000000000006" damping="0.00012950000000000003"/>
<geom name="IDR0_b_3_g" type="box" size="0.0005 0.0175 0.0010416666666666667" pos="0 0 0.0010416666666666667" rgba="0.1 0.1 0.1 0.5"/>
<site name="IDR0_b_3_s" size="0.0001" pos="0 0 0.0010416666666666667"/>
<body name="IDR0_b_4" pos="0 0 0.0020833333333333333" euler="0 0 0">
<joint name="IDR0_b_4_j" type="hinge" axis="0 1 0" pos="0 0 0" stiffness="0.025900000000000006" damping="0.00012950000000000003"/>
<geom name="IDR0_b_4_g" type="box" size="0.0005 0.0175 0.0010416666666666667" pos="0 0 0.0010416666666666667" rgba="0.1 0.1 0.1 0.5"/>
<site name="IDR0_b_4_s" size="0.0001" pos="0 0 0.0010416666666666667"/>
<body name="IDR0_b_5" pos="0 0 0.0020833333333333333" euler="0 0 0">
<joint name="IDR0_b_5_j" type="hinge" axis="0 1 0" pos="0 0 0" stiffness="0.025900000000000006" damping="0.00012950000000000003"/>
<geom name="IDR0_b_5_g" type="box" size="0.0005 0.0175 0.0010416666666666667" pos="0 0 0.0010416666666666667" rgba="0.1 0.1 0.1 0.5"/>
<site name="IDR0_b_5_s" size="0.0001" pos="0 0 0.0010416666666666667"/>
<body name="IDR0_b_6" pos="0 0 0.0020833333333333333" euler="0 0 0">
<joint name="IDR0_b_6_j" type="hinge" axis="0 1 0" pos="0 0 0" stiffness="0.025900000000000006" damping="0.00012950000000000003"/>
<geom name="IDR0_b_6_g" type="box" size="0.0005 0.0175 0.0010416666666666667" pos="0 0 0.0010416666666666667" rgba="0.1 0.1 0.1 0.5"/>
<site name="IDR0_b_6_s" size="0.0001" pos="0 0 0.0010416666666666667"/>
<body name="IDR0_b_7" pos="0 0 0.0020833333333333333" euler="0 0 0">
<joint name="IDR0_b_7_j" type="hinge" axis="0 1 0" pos="0 0 0" stiffness="0.025900000000000006" damping="0.00012950000000000003"/>
<geom name="IDR0_b_7_g" type="box" size="0.0005 0.0175 0.0010416666666666667" pos="0 0 0.0010416666666666667" rgba="0.1 0.1 0.1 0.5"/>
<site name="IDR0_b_7_s" size="0.0001" pos="0 0 0.0010416666666666667"/>
<body name="IDR0_b_8" pos="0 0 0.0020833333333333333" euler="0 0 0">
<joint name="IDR0_b_8_j" type="hinge" axis="0 1 0" pos="0 0 0" stiffness="0.025900000000000006" damping="0.00012950000000000003"/>
<geom name="IDR0_b_8_g" type="box" size="0.0005 0.0175 0.0010416666666666667" pos="0 0 0.0010416666666666667" rgba="0.1 0.1 0.1 0.5"/>
<site name="IDR0_b_8_s" size="0.0001" pos="0 0 0.0010416666666666667"/>
<body name="IDR0_b_9" pos="0 0 0.0020833333333333333" euler="0 0 0">
<joint name="IDR0_b_9_j" type="hinge" axis="0 1 0" pos="0 0 0" stiffness="0.025900000000000006" damping="0.00012950000000000003"/>
<geom name="IDR0_b_9_g" type="box" size="0.0005 0.0175 0.0010416666666666667" pos="0 0 0.0010416666666666667" rgba="0.1 0.1 0.1 0.5"/>
<site name="IDR0_b_9_s" size="0.0001" pos="0 0 0.0010416666666666667"/>
<body name="IDR0_b_10" pos="0 0 0.0020833333333333333" euler="0 0 0">
<joint name="IDR0_b_10_j" type="hinge" axis="0 1 0" pos="0 0 0" stiffness="0.025900000000000006" damping="0.00012950000000000003"/>
<geom name="IDR0_b_10_g" type="box" size="0.0005 0.0175 0.0010416666666666667" pos="0 0 0.0010416666666666667" rgba="0.1 0.1 0.1 0.5"/>
<site name="IDR0_b_10_s" size="0.0001" pos="0 0 0.0010416666666666667"/>
<body name="IDR0_b_11" pos="0 0 0.0020833333333333333" euler="0 0 0">
<joint name="IDR0_b_11_j" type="hinge" axis="0 1 0" pos="0 0 0" stiffness="0.025900000000000006" damping="0.00012950000000000003"/>
<geom name="IDR0_b_11_g" type="box" size="0.0005 0.0175 0.0010416666666666667" pos="0 0 0.0010416666666666667" rgba="0.1 0.1 0.1 0.5"/>
<site name="IDR0_b_11_s" size="0.0001" pos="0 0 0.0010416666666666667"/>
<body name="IDR0_b_12" pos="0 0 0.0020833333333333333" euler="0 0 0">
<joint name="IDR0_b_12_j" type="hinge" axis="0 1 0" pos="0 0 0" stiffness="0.025900000000000006" damping="0.00012950000000000003"/>
<geom name="IDR0_b_12_g" type="box" size="0.0005 0.0175 0.0005208333333333333" pos="0 0 0.0005208333333333333" rgba="0.1 0.1 0.1 0.5"/>
<site name="IDR0_b_12_s" size="0.0001" pos="0 0 0.0005208333333333333"/>
<site name="IDR0_b_13_s" size="0.0001" pos="0 0 0.0010416666666666667"/>
</body>
</body>
</body>
</body>
</body>
</body>
</body>
</body>
</body>
</body>
</body>
</body>
</body>
</body><body>
<joint type="free"/>
<body name="IDR1_b_0" pos="0 0 0.02176326980708465" euler="0 80.0 0">
<site name="IDR1_b_0_sroot" size="0.0001" pos="0 0 0"/>
<geom name="IDR1_b_0_g" type="box" size="0.0005 0.0175 0.0004688792548793036" pos="0 0 0.0004688792548793036" rgba="0.1 0.1 0.1 0.5"/>
<site name="IDR1_b_0_s" size="0.0001" pos="0 0 0.0004688792548793036"/>
<body name="IDR1_b_1" pos="0 0 0.0009377585097586072" euler="0 0 0">
<joint name="IDR1_b_1_j" type="hinge" axis="0 1 0" pos="0 0 0" stiffness="0.02876984467313606" damping="0.0001438492233656803"/>
<geom name="IDR1_b_1_g" type="box" size="0.0005 0.0175 0.0009377585097586072" pos="0 0 0.0009377585097586072" rgba="0.1 0.1 0.1 0.5"/>
<site name="IDR1_b_1_s" size="0.0001" pos="0 0 0.0009377585097586072"/>
<body name="IDR1_b_2" pos="0 0 0.0018755170195172144" euler="0 0 0">
<joint name="IDR1_b_2_j" type="hinge" axis="0 1 0" pos="0 0 0" stiffness="0.02876984467313606" damping="0.0001438492233656803"/>
<geom name="IDR1_b_2_g" type="box" size="0.0005 0.0175 0.0009377585097586072" pos="0 0 0.0009377585097586072" rgba="0.1 0.1 0.1 0.5"/>
<site name="IDR1_b_2_s" size="0.0001" pos="0 0 0.0009377585097586072"/>
<body name="IDR1_b_3" pos="0 0 0.0018755170195172144" euler="0 0 0">
<joint name="IDR1_b_3_j" type="hinge" axis="0 1 0" pos="0 0 0" stiffness="0.02876984467313606" damping="0.0001438492233656803"/>
<geom name="IDR1_b_3_g" type="box" size="0.0005 0.0175 0.0009377585097586072" pos="0 0 0.0009377585097586072" rgba="0.1 0.1 0.1 0.5"/>
<site name="IDR1_b_3_s" size="0.0001" pos="0 0 0.0009377585097586072"/>
<body name="IDR1_b_4" pos="0 0 0.0018755170195172144" euler="0 0 0">
<joint name="IDR1_b_4_j" type="hinge" axis="0 1 0" pos="0 0 0" stiffness="0.02876984467313606" damping="0.0001438492233656803"/>
<geom name="IDR1_b_4_g" type="box" size="0.0005 0.0175 0.0009377585097586072" pos="0 0 0.0009377585097586072" rgba="0.1 0.1 0.1 0.5"/>
<site name="IDR1_b_4_s" size="0.0001" pos="0 0 0.0009377585097586072"/>
<body name="IDR1_b_5" pos="0 0 0.0018755170195172144" euler="0 0 0">
<joint name="IDR1_b_5_j" type="hinge" axis="0 1 0" pos="0 0 0" stiffness="0.02876984467313606" damping="0.0001438492233656803"/>
<geom name="IDR1_b_5_g" type="box" size="0.0005 0.0175 0.0009377585097586072" pos="0 0 0.0009377585097586072" rgba="0.1 0.1 0.1 0.5"/>
<site name="IDR1_b_5_s" size="0.0001" pos="0 0 0.0009377585097586072"/>
<body name="IDR1_b_6" pos="0 0 0.0018755170195172144" euler="0 0 0">
<joint name="IDR1_b_6_j" type="hinge" axis="0 1 0" pos="0 0 0" stiffness="0.02876984467313606" damping="0.0001438492233656803"/>
<geom name="IDR1_b_6_g" type="box" size="0.0005 0.0175 0.0009377585097586072" pos="0 0 0.0009377585097586072" rgba="0.1 0.1 0.1 0.5"/>
<site name="IDR1_b_6_s" size="0.0001" pos="0 0 0.0009377585097586072"/>
<body name="IDR1_b_7" pos="0 0 0.0018755170195172144" euler="0 0 0">
<joint name="IDR1_b_7_j" type="hinge" axis="0 1 0" pos="0 0 0" stiffness="0.02876984467313606" damping="0.0001438492233656803"/>
<geom name="IDR1_b_7_g" type="box" size="0.0005 0.0175 0.0009377585097586072" pos="0 0 0.0009377585097586072" rgba="0.1 0.1 0.1 0.5"/>
<site name="IDR1_b_7_s" size="0.0001" pos="0 0 0.0009377585097586072"/>
<body name="IDR1_b_8" pos="0 0 0.0018755170195172144" euler="0 0 0">
<joint name="IDR1_b_8_j" type="hinge" axis="0 1 0" pos="0 0 0" stiffness="0.02876984467313606" damping="0.0001438492233656803"/>
<geom name="IDR1_b_8_g" type="box" size="0.0005 0.0175 0.0009377585097586072" pos="0 0 0.0009377585097586072" rgba="0.1 0.1 0.1 0.5"/>
<site name="IDR1_b_8_s" size="0.0001" pos="0 0 0.0009377585097586072"/>
<body name="IDR1_b_9" pos="0 0 0.0018755170195172144" euler="0 0 0">
<joint name="IDR1_b_9_j" type="hinge" axis="0 1 0" pos="0 0 0" stiffness="0.02876984467313606" damping="0.0001438492233656803"/>
<geom name="IDR1_b_9_g" type="box" size="0.0005 0.0175 0.0009377585097586072" pos="0 0 0.0009377585097586072" rgba="0.1 0.1 0.1 0.5"/>
<site name="IDR1_b_9_s" size="0.0001" pos="0 0 0.0009377585097586072"/>
<body name="IDR1_b_10" pos="0 0 0.0018755170195172144" euler="0 0 0">
<joint name="IDR1_b_10_j" type="hinge" axis="0 1 0" pos="0 0 0" stiffness="0.02876984467313606" damping="0.0001438492233656803"/>
<geom name="IDR1_b_10_g" type="box" size="0.0005 0.0175 0.0009377585097586072" pos="0 0 0.0009377585097586072" rgba="0.1 0.1 0.1 0.5"/>
<site name="IDR1_b_10_s" size="0.0001" pos="0 0 0.0009377585097586072"/>
<body name="IDR1_b_11" pos="0 0 0.0018755170195172144" euler="0 0 0">
<joint name="IDR1_b_11_j" type="hinge" axis="0 1 0" pos="0 0 0" stiffness="0.02876984467313606" damping="0.0001438492233656803"/>
<geom name="IDR1_b_11_g" type="box" size="0.0005 0.0175 0.0009377585097586072" pos="0 0 0.0009377585097586072" rgba="0.1 0.1 0.1 0.5"/>
<site name="IDR1_b_11_s" size="0.0001" pos="0 0 0.0009377585097586072"/>
<body name="IDR1_b_12" pos="0 0 0.0018755170195172144" euler="0 0 0">
<joint name="IDR1_b_12_j" type="hinge" axis="0 1 0" pos="0 0 0" stiffness="0.02876984467313606" damping="0.0001438492233656803"/>
<geom name="IDR1_b_12_g" type="box" size="0.0005 0.0175 0.0004688792548793036" pos="0 0 0.0004688792548793036" rgba="0.1 0.1 0.1 0.5"/>
<site name="IDR1_b_12_s" size="0.0001" pos="0 0 0.0004688792548793036"/>
<site name="IDR1_b_13_s" size="0.0001" pos="0 0 0.0009377585097586072"/>
</body>
</body>
</body>
</body>
</body>
</body>
</body>
</body>
</body>
</body>
</body>
</body>
</body>
</body><body>
<joint type="free"/>
<body name="IDR2_b_0" pos="0 0 0.01823673019291535" euler="0 100.0 0">
<site name="IDR2_b_0_sroot" size="0.0001" pos="0 0 0"/>
<geom name="IDR2_b_0_g" type="box" size="0.00075 0.0175 0.0006004571671693622" pos="0 0 0.0006004571671693622" rgba="0.1 0.1 0.1 0.5"/>
<site name="IDR2_b_0_s" size="0.0001" pos="0 0 0.0006004571671693622"/>
<body name="IDR2_b_1" pos="0 0 0.0012009143343387244" euler="0 0 0">
<joint name="IDR2_b_1_j" type="hinge" axis="0 1 0" pos="0 0 0" stiffness="0.07582113469412344" damping="0.0003791056734706172"/>
<geom name="IDR2_b_1_g" type="box" size="0.00075 0.0175 0.0012009143343387244" pos="0 0 0.0012009143343387244" rgba="0.1 0.1 0.1 0.5"/>
<site name="IDR2_b_1_s" size="0.0001" pos="0 0 0.0012009143343387244"/>
<body name="IDR2_b_2" pos="0 0 0.002401828668677449" euler="0 0 0">
<joint name="IDR2_b_2_j" type="hinge" axis="0 1 0" pos="0 0 0" stiffness="0.07582113469412344" damping="0.0003791056734706172"/>
<geom name="IDR2_b_2_g" type="box" size="0.00075 0.0175 0.0012009143343387244" pos="0 0 0.0012009143343387244" rgba="0.1 0.1 0.1 0.5"/>
<site name="IDR2_b_2_s" size="0.0001" pos="0 0 0.0012009143343387244"/>
<body name="IDR2_b_3" pos="0 0 0.002401828668677449" euler="0 0 0">
<joint name="IDR2_b_3_j" type="hinge" axis="0 1 0" pos="0 0 0" stiffness="0.07582113469412344" damping="0.0003791056734706172"/>
<geom name="IDR2_b_3_g" type="box" size="0.00075 0.0175 0.0012009143343387244" pos="0 0 0.0012009143343387244" rgba="0.1 0.1 0.1 0.5"/>
<site name="IDR2_b_3_s" size="0.0001" pos="0 0 0.0012009143343387244"/>
<body name="IDR2_b_4" pos="0 0 0.002401828668677449" euler="0 0 0">
<joint name="IDR2_b_4_j" type="hinge" axis="0 1 0" pos="0 0 0" stiffness="0.07582113469412344" damping="0.0003791056734706172"/>
<geom name="IDR2_b_4_g" type="box" size="0.00075 0.0175 0.0012009143343387244" pos="0 0 0.0012009143343387244" rgba="0.1 0.1 0.1 0.5"/>
<site name="IDR2_b_4_s" size="0.0001" pos="0 0 0.0012009143343387244"/>
<body name="IDR2_b_5" pos="0 0 0.002401828668677449" euler="0 0 0">
<joint name="IDR2_b_5_j" type="hinge" axis="0 1 0" pos="0 0 0" stiffness="0.07582113469412344" damping="0.0003791056734706172"/>
<geom name="IDR2_b_5_g" type="box" size="0.00075 0.0175 0.0012009143343387244" pos="0 0 0.0012009143343387244" rgba="0.1 0.1 0.1 0.5"/>
<site name="IDR2_b_5_s" size="0.0001" pos="0 0 0.0012009143343387244"/>
<body name="IDR2_b_6" pos="0 0 0.002401828668677449" euler="0 0 0">
<joint name="IDR2_b_6_j" type="hinge" axis="0 1 0" pos="0 0 0" stiffness="0.07582113469412344" damping="0.0003791056734706172"/>
<geom name="IDR2_b_6_g" type="box" size="0.00075 0.0175 0.0012009143343387244" pos="0 0 0.0012009143343387244" rgba="0.1 0.1 0.1 0.5"/>
<site name="IDR2_b_6_s" size="0.0001" pos="0 0 0.0012009143343387244"/>
<body name="IDR2_b_7" pos="0 0 0.002401828668677449" euler="0 0 0">
<joint name="IDR2_b_7_j" type="hinge" axis="0 1 0" pos="0 0 0" stiffness="0.07582113469412344" damping="0.0003791056734706172"/>
<geom name="IDR2_b_7_g" type="box" size="0.00075 0.0175 0.0012009143343387244" pos="0 0 0.0012009143343387244" rgba="0.1 0.1 0.1 0.5"/>
<site name="IDR2_b_7_s" size="0.0001" pos="0 0 0.0012009143343387244"/>
<body name="IDR2_b_8" pos="0 0 0.002401828668677449" euler="0 0 0">
<joint name="IDR2_b_8_j" type="hinge" axis="0 1 0" pos="0 0 0" stiffness="0.07582113469412344" damping="0.0003791056734706172"/>
<geom name="IDR2_b_8_g" type="box" size="0.00075 0.0175 0.0012009143343387244" pos="0 0 0.0012009143343387244" rgba="0.1 0.1 0.1 0.5"/>
<site name="IDR2_b_8_s" size="0.0001" pos="0 0 0.0012009143343387244"/>
<body name="IDR2_b_9" pos="0 0 0.002401828668677449" euler="0 0 0">
<joint name="IDR2_b_9_j" type="hinge" axis="0 1 0" pos="0 0 0" stiffness="0.07582113469412344" damping="0.0003791056734706172"/>
<geom name="IDR2_b_9_g" type="box" size="0.00075 0.0175 0.0012009143343387244" pos="0 0 0.0012009143343387244" rgba="0.1 0.1 0.1 0.5"/>
<site name="IDR2_b_9_s" size="0.0001" pos="0 0 0.0012009143343387244"/>
<body name="IDR2_b_10" pos="0 0 0.002401828668677449" euler="0 0 0">
<joint name="IDR2_b_10_j" type="hinge" axis="0 1 0" pos="0 0 0" stiffness="0.07582113469412344" damping="0.0003791056734706172"/>
<geom name="IDR2_b_10_g" type="box" size="0.00075 0.0175 0.0012009143343387244" pos="0 0 0.0012009143343387244" rgba="0.1 0.1 0.1 0.5"/>
<site name="IDR2_b_10_s" size="0.0001" pos="0 0 0.0012009143343387244"/>
<body name="IDR2_b_11" pos="0 0 0.002401828668677449" euler="0 0 0">
<joint name="IDR2_b_11_j" type="hinge" axis="0 1 0" pos="0 0 0" stiffness="0.07582113469412344" damping="0.0003791056734706172"/>
<geom name="IDR2_b_11_g" type="box" size="0.00075 0.0175 0.0012009143343387244" pos="0 0 0.0012009143343387244" rgba="0.1 0.1 0.1 0.5"/>
<site name="IDR2_b_11_s" size="0.0001" pos="0 0 0.0012009143343387244"/>
<body name="IDR2_b_12" pos="0 0 0.002401828668677449" euler="0 0 0">
<joint name="IDR2_b_12_j" type="hinge" axis="0 1 0" pos="0 0 0" stiffness="0.07582113469412344" damping="0.0003791056734706172"/>
<geom name="IDR2_b_12_g" type="box" size="0.00075 0.0175 0.0006004571671693622" pos="0 0 0.0006004571671693622" rgba="0.1 0.1 0.1 0.5"/>
<site name="IDR2_b_12_s" size="0.0001" pos="0 0 0.0006004571671693622"/>
<site name="IDR2_b_13_s" size="0.0001" pos="0 0 0.0012009143343387244"/>
</body>
</body>
</body>
</body>
</body>
</body>
</body>
</body>
</body>
</body>
</body>
</body>
</body>
</body><site name="focal_site" pos="-0.01 0 0.02" size="0.001" rgba="0 1 0 0.1" type="sphere"/><geom name="focal_line_0" type="cylinder" pos="-0.005 0.0 0.02" quat="0.7071067811865476 0 0.7071067811865476 0" size="0.0005 0.005" rgba="0 1 0 0.1" contype="0" conaffinity="0"/><geom name="focal_line_1" type="cylinder" pos="-0.005 0.0 0.020881634903542327" quat="0.766044443118978 0 0.6427876096865393 0" size="0.0005 0.005077133059428725" rgba="0 1 0 0.1" contype="0" conaffinity="0"/><geom name="focal_line_2" type="cylinder" pos="-0.005 0.0 0.019118365096457673" quat="0.6427876096865393 0 0.7660444431189781 0" size="0.0005 0.005077133059428725" rgba="0 1 0 0.1" contype="0" conaffinity="0"/><body name="moving_cylinder" pos="-0.031 0 0.04" euler="90 0 0"><joint name="slider_joint" type="slide" axis="1 0 0" limited="true" range="-0.5 0.5" damping="1"/><geom name="moving_cylinder_geom" type="cylinder" pos="0 0 0" size="0.03 0.1" rgba="0.8 0.2 0.2 0.4" euler="0 0 90" condim="4" contype="1" conaffinity="15" friction="0.9 0.2 0.2" solref="0.001 2"/><site name="cylinder_site" pos="0 0 0" size="0.001" rgba="0 0 1 1"/></body></worldbody>

<equality><weld name="connect_fin" site1="IDF_b_21_s" site2="IDB_b_21_s"/><weld name="connect_rib_A0" site1="IDF_b_6_conn_0" site2="IDR0_b_0_sroot"/><weld name="connect_rib_B0" site1="IDB_b_6_conn_0" site2="IDR0_b_13_s"/><weld name="connect_rib_A1" site1="IDF_b_6_conn_1" site2="IDR1_b_0_sroot"/><weld name="connect_rib_B1" site1="IDB_b_7_conn_1" site2="IDR1_b_13_s"/><weld name="connect_rib_A2" site1="IDF_b_5_conn_2" site2="IDR2_b_0_sroot"/><weld name="connect_rib_B2" site1="IDB_b_4_conn_2" site2="IDR2_b_13_s"/></equality><actuator>
<position name="cylinder_actuator" joint="slider_joint" kp="20000" dampratio="1" ctrlrange="-0.5 0.5"/></actuator>


</mujoco>
